Workbook

Sheet README
B2: Bond Portfolio Convexity Sensitivity — Excel / Power BI Model
B5: This workbook accompanies the Python/R analytics engine and ML models.
B7: Sheets:
B8: Bond_Data Raw 300-bond portfolio (source of truth for all formulas)
B9: Portfolio_Summary Live KPIs (duration, convexity, DV01, YTM) + shift sensitivity table & chart
B10: Bucket_Exposure Key-rate bucket duration/convexity contribution (SUMIFS/SUMPRODUCT)
B11: Sector_Exposure Sector concentration and risk profile
B12: Scenario_Data 1,000 Monte Carlo yield-curve scenarios (raw)
B13: VaR_Analysis VaR / CVaR at 90/95/99% + distribution statistics (all live formulas)
B14: PowerBI_DAX_Measures DAX code to paste into a Power BI model built on the same tables
B16: Color coding: Blue = input/selectable cell, Black = formula, Green = cross-sheet link.
B17: All KPI and risk figures recalculate automatically if Bond_Data or Scenario_Data change.

Sheet Bond_Data
A1: BondID | B1: ISIN | C1: Issuer | D1: Sector | E1: CreditRating | F1: Currency | G1: FaceValue | H1: CouponRate | I1: CouponFrequency | J1: BondType | K1: IssueDate | L1: MaturityDate | M1: ValuationDate | N1: YearsToMaturity | O1: OriginalMaturityYears | P1: YieldToMaturity | Q1: CleanPrice | R1: AccruedInterest | S1: DirtyPrice | T1: MacaulayDuration | U1: ModifiedDuration | V1: Convexity | W1: DV01_Per100Face | X1: EffectiveDuration | Y1: EffectiveConvexity | Z1: SpreadOverBenchmark_bps | AA1: OAS_bps | AB1: ZSpread_bps | AC1: KeyRateBucket | AD1: Quantity | AE1: MarketValue_LocalCcy | AF1: MarketValue_INR | AG1: PortfolioWeight | AH1: IsCallable | AI1: CallDate | AJ1: IsPutable | AK1: IsFloatingRate | AL1: BenchmarkIndex | AM1: PriceChange_Up50bps | AN1: PriceChange_Dn50bps | AO1: PriceChange_Up100bps | AP1: PriceChange_Dn100bps | AQ1: PriceChange_Up200bps | AR1: PriceChange_Dn200bps
A2: ZTFI-0001 | B2: IN1043321819 | C2: Government of India | D2: Government | E2: SOV | F2: INR | G2: 100 | H2: 0.062 | I2: 2 | J2: Fixed | K2: 2024-02-24 | L2: 2027-02-23 | M2: 2024-10-31 | N2: 2.3135 | O2: 3 | P2: 0.0674 | Q2: 99.0052 | R2: 0.0411 | S2: 99.3134 | T2: 1.9111 | U2: 1.8488 | V2: 4.4027 | W2: 0.0183 | X2: 1.8488 | Y2: 4.4027 | Z2: 0 | AA2: 0 | AB2: 8 | AC2: 2-3Y | AD2: 100000 | AE2: 99005.2 | AF2: 99005.2 | AG2: 0.003088 | AH2: =FALSE() -> FALSE | AJ2: =FALSE() -> FALSE | AK2: =FALSE() -> FALSE | AL2: IN10YT | AM2: 0.9207 | AN2: -0.9098 | AO2: 1.8522 | AP2: -1.8086 | AQ2: 3.748 | AR2: -3.5736
A3: ZTFI-0002 | B3: IN7940265423 | C3: Government of India | D3: Government | E3: SOV | F3: INR | G3: 100 | H3: 0.0773 | I3: 2 | J3: Fixed | K3: 2022-11-08 | L3: 2045-11-02 | M3: 2024-10-31 | N3: 21.0048 | O3: 23 | P3: 0.069 | Q3: 109.1347 | R3: 1.6378 | S3: 110.3014 | T3: 11.1303 | U3: 10.7591 | V3: 170.9441 | W3: 0.1174 | X3: 10.7591 | Y3: 170.9441 | Z3: 0 | AA3: 0 | AB3: -4 | AC3: 20Y+ | AD3: 20000 | AE3: 21826.94 | AF3: 21826.94 | AG3: 0.000681 | AH3: =FALSE() -> FALSE | AJ3: =FALSE() -> FALSE | AK3: =FALSE() -> FALSE | AL3: IN10YT | AM3: 6.1042 | AN3: -5.6378 | AO3: 12.6747 | AP3: -10.8091 | AQ3: 27.215 | AR3: -19.7526
A4: ZTFI-0003 | B4: IN7816184959 | C4: Government of India | D4: Government | E4: SOV | F4: INR | G4: 100 | H4: 0.0555 | I4: 2 | J4: Fixed | K4: 2024-02-08 | L4: 2030-02-06 | M4: 2024-10-31 | N4: 5.2676 | O4: 6 | P4: 0.0674 | Q4: 95.019 | R4: 1.367 | S4: 96.2058 | T4: 4.4165 | U4: 4.2725 | V4: 21.7752 | W4: 0.0406 | X4: 4.2725 | Y4: 21.7752 | Z4: 0 | AA4: 0 | AB4: -2 | AC4: 5-7Y | AD4: 20000 | AE4: 19003.8 | AF4: 19003.8 | AG4: 0.000593 | AH4: =FALSE() -> FALSE | AJ4: =FALSE() -> FALSE | AK4: =FALSE() -> FALSE | AL4: IN10YT | AM4: 2.0557 | AN4: -2.004 | AO4: 4.1631 | AP4: -3.9562 | AQ4: 8.5332 | AR4: -7.7056
A5: ZTFI-0004 | B5: IN4752553419 | C5: Government of India | D5: Government | E5: SOV | F5: INR | G5: 100 | H5: 0.0681 | I5: 2 | J5: Fixed | K5: 2013-10-08 | L5: 2049-09-29 | M5: 2024-10-31 | N5: 24.9117 | O5: 36 | P5: 0.0667 | Q5: 101.6783 | R5: 0.4596 | S5: 103.2538 | T5: 12.3379 | U5: 11.9397 | V5: 215.5283 | W5: 0.1214 | X5: 11.9397 | Y5: 215.5283 | Z5: 0 | AA5: 0 | AB5: 2 | AC5: 20Y+ | AD5: 50000 | AE5: 50839.15 | AF5: 50839.15 | AG5: 0.001586 | AH5: =FALSE() -> FALSE | AJ5: =FALSE() -> FALSE | AK5: =FALSE() -> FALSE | AL5: IN10YT | AM5: 6.344 | AN5: -5.7961 | AO5: 13.2358 | AP5: -11.0444 | AQ5: 28.6631 | AR5: -19.8973
A6: ZTFI-0005 | B6: IN5030564139 | C6: Government of India | D6: Government | E6: SOV | F6: INR | G6: 100 | H6: 0.075 | I6: 2 | J6: Fixed | K6: 2021-04-03 | L6: 2043-03-29 | M6: 2024-10-31 | N6: 18.4066 | O6: 22 | P6: 0.0702 | Q6: 104.8627 | R6: 0.8603 | S6: 105.3594 | T6: 10.3448 | U6: 9.994 | V6: 142.4173 | W6: 0.1048 | X6: 9.994 | Y6: 142.4173 | Z6: 0 | AA6: 0 | AB6: 2 | AC6: 15-20Y | AD6: 200000 | AE6: 209725.4 | AF6: 209725.4 | AG6: 0.006542 | AH6: =FALSE() -> FALSE | AJ6: =FALSE() -> FALSE | AK6: =FALSE() -> FALSE | AL6: IN10YT | AM6: 5.4267 | AN6: -5.0533 | AO6: 11.2267 | AP6: -9.7333 | AQ6: 23.9468 | AR6: -17.9731
A7: ZTFI-0006 | B7: IN8849696532 | C7: Government of India | D7: Government | E7: SOV | F7: INR | G7: 100 | H7: 0.0645 | I7: 2 | J7: Fixed | K7: 2019-10-21 | L7: 2026-10-19 | M7: 2024-10-31 | N7: 1.9658 | O7: 7 | P7: 0.074 | Q7: 98.6743 | R7: 1.0118 | S7: 99.9515 | T7: 1.4533 | U7: 1.4014 | V7: 2.6741 | W7: 0.0138 | X7: 1.4014 | Y7: 2.6741 | Z7: 0 | AA7: 0 | AB7: 8 | AC7: 1-2Y | AD7: 10000 | AE7: 9867.43 | AF7: 9867.43 | AG7: 0.000308 | AH7: =FALSE() -> FALSE | AJ7: =FALSE() -> FALSE | AK7: =FALSE() -> FALSE | AL7: IN10YT | AM7: 0.6947 | AN7: -0.6881 | AO7: 1.396 | AP7: -1.3696 | AQ7: 2.8184 | AR7: -2.7129
A8: ZTFI-0007 | B8: IN1669784801 | C8: Government of India | D8: Government | E8: SOV | F8: INR | G8: 100 | H8: 0.0694 | I8: 2 | J8: Fixed | K8: 2013-06-15 | L8: 2049-06-06 | M8: 2024-10-31 | N8: 24.5969 | O8: 36 | P8: 0.0731 | Q8: 95.8101 | R8: 0.1935 | S8: 96.5644 | T8: 11.854 | U8: 11.436 | V8: 201.833 | W8: 0.1096 | X8: 11.436 | Y8: 201.833 | Z8: 0 | AA8: 0 | AB8: 9 | AC8: 20Y+ | AD8: 20000 | AE8: 19162.02 | AF8: 19162.02 | AG8: 0.000598 | AH8: =FALSE() -> FALSE | AJ8: =FALSE() -> FALSE | AK8: =FALSE() -> FALSE | AL8: IN10YT | AM8: 5.7201 | AN8: -5.2367 | AO8: 11.9237 | AP8: -9.99 | AQ8: 25.7812 | AR8: -18.0462
A9: ZTFI-0008 | B9: IN4828148932 | C9: Government of India | D9: Government | E9: SOV | F9: INR | G9: 100 | H9: 0.0607 | I9: 2 | J9: Fixed | K9: 2018-05-28 | L9: 2030-05-25 | M9: 2024-10-31 | N9: 5.5633 | O9: 12 | P9: 0.0732 | Q9: 94.4229 | R9: 1.3938 | S9: 95.3318 | T9: 4.7315 | U9: 4.5644 | V9: 25.0647 | W9: 0.0431 | X9: 4.5644 | Y9: 25.0647 | Z9: 0 | AA9: 0 | AB9: 10 | AC9: 5-7Y | AD9: 100000 | AE9: 94422.9 | AF9: 94422.9 | AG9: 0.002945 | AH9: =FALSE() -> FALSE | AJ9: =FALSE() -> FALSE | AK9: =FALSE() -> FALSE | AL9: IN10YT | AM9: 2.1845 | AN9: -2.1253 | AO9: 4.4282 | AP9: -4.1915 | AQ9: 9.093 | AR9: -8.1463
A10: ZTFI-0009 | B10: IN1543039117 | C10: Government of India | D10: Government | E10: SOV | F10: INR | G10: 100 | H10: 0.0733 | I10: 2 | J10: Fixed | K10: 2013-03-28 | L10: 2049-03-19 | M10: 2024-10-31 | N10: 24.3806 | O10: 36 | P10: 0.0663 | Q10: 108.3514 | R10: 1.7351 | S10: 108.654 | T10: 12.0883 | U10: 11.7004 | V10: 206.5622 | W10: 0.1268 | X10: 11.7004 | Y10: 206.5622 | Z10: 0 | AA10: 0 | AB10: 8 | AC10: 20Y+ | AD10: 50000 | AE10: 54175.7 | AF10: 54175.7 | AG10: 0.00169 | AH10: =FALSE() -> FALSE | AJ10: =FALSE() -> FALSE | AK10: =FALSE() -> FALSE | AL10: IN10YT | AM10: 6.6185 | AN10: -6.059 | AO10: 13.7966 | AP10: -11.5585 | AQ10: 29.8314 | AR10: -20.8788
A11: ZTFI-0010 | B11: IN8346578713 | C11: Government of India | D11: Government | E11: SOV | F11: INR | G11: 100 | H11: 0.0564 | I11: 2 | J11: Fixed | K11: 2024-01-12 | L11: 2047-01-06 | M11: 2024-10-31 | N11: 22.1821 | O11: 23 | P11: 0.0708 | Q11: 84.0622 | R11: 0.3105 | S11: 84.1623 | T11: 12.0116 | U11: 11.6009 | V11: 197.3753 | W11: 0.0975 | X11: 11.6009 | Y11: 197.3753 | Z11: 0 | AA11: 0 | AB11: -4 | AC11: 20Y+ | AD11: 100000 | AE11: 84062.2 | AF11: 84062.2 | AG11: 0.002622 | AH11: =FALSE() -> FALSE | AJ11: =FALSE() -> FALSE | AK11: =FALSE() -> FALSE | AL11: IN10YT | AM11: 5.0834 | AN11: -4.6686 | AO11: 10.5816 | AP11: -8.9224 | AQ11: 22.8223 | AR11: -16.1856
A12: ZTFI-0011 | B12: IN1051834738 | C12: Government of India | D12: Government | E12: SOV | F12: INR | G12: 100 | H12: 0.0538 | I12: 2 | J12: Fixed | K12: 2015-12-26 | L12: 2053-12-16 | M12: 2024-10-31 | N12: 29.1253 | O12: 38 | P12: 0.0676 | Q12: 82.5548 | R12: 1.0861 | S12: 82.8109 | T12: 13.6417 | U12: 13.1957 | V12: 272.9803 | W12: 0.1089 | X12: 13.1957 | Y12: 272.9803 | Z12: 0 | AA12: 0 | AB12: -2 | AC12: 20Y+ | AD12: 50000 | AE12: 41277.4 | AF12: 41277.4 | AG12: 0.001288 | AH12: =FALSE() -> FALSE | AJ12: =FALSE() -> FALSE | AK12: =FALSE() -> FALSE | AL12: IN10YT | AM12: 5.7285 | AN12: -5.1651 | AO12: 12.0205 | AP12: -9.7669 | AQ12: 26.2945 | AR12: -17.2802
A13: ZTFI-0012 | B13: IN6566701065 | C13: Government of India | D13: Government | E13: SOV | F13: INR | G13: 100 | H13: 0.0728 | I13: 2 | J13: Fixed | K13: 2022-08-06 | L13: 2030-08-04 | M13: 2024-10-31 | N13: 5.7577 | O13: 8 | P13: 0.067 | Q13: 102.632 | R13: 0.2551 | S13: 102.9659 | T13: 4.6424 | U13: 4.4919 | V13: 24.5493 | W13: 0.0461 | X13: 4.4919 | Y13: 24.5493 | Z13: 0 | AA13: 0 | AB13: 9 | AC13: 5-7Y | AD13: 50000 | AE13: 51316 | AF13: 51316 | AG13: 0.001601 | AH13: =FALSE() -> FALSE | AJ13: =FALSE() -> FALSE | AK13: =FALSE() -> FALSE | AL13: IN10YT | AM13: 2.3366 | AN13: -2.2736 | AO13: 4.7361 | AP13: -4.4841 | AQ13: 9.7242 | AR13: -8.7163
... A117: ZTFI-0116 | B117: IN7833918785 | C117: IRFC | D117: Infrastructure | E117: AAA | F117: INR | G117: 100 | H117: 0.0716 | I117: 2 | J117: Fixed | K117: 2024-03-18 | L117: 2027-03-18 | M117: 2024-10-31 | N117: 2.3765 | O117: 3 | P117: 0.0821 | Q117: 98.099 | R117: 0.2682 | S117: 98.6863 | T117: 1.8976 | U117: 1.8228 | V117: 4.2995 | W117: 0.0179 | X117: 1.8228 | Y117: 4.2995 | Z117: 32 | AA117: 32 | AB117: 41 | AC117: 2-3Y | AD117: 100000 | AE117: 98099 | AF117: 98099 | AG117: 0.00306 | AH117: =FALSE() -> FALSE | AJ117: =FALSE() -> FALSE | AK117: =FALSE() -> FALSE | AL117: IN10YT | AM117: 0.8993 | AN117: -0.8888 | AO117: 1.8092 | AP117: -1.7671 | AQ117: 3.6607 | AR117: -3.4919
A118: ZTFI-0117 | B118: IN3971870728 | C118: HDFC Bank | D118: Infrastructure | E118: AAA | F118: INR | G118: 100 | H118: 0.0783 | I118: 2 | J118: Fixed | K118: 2023-10-11 | L118: 2025-10-10 | M118: 2024-10-31 | N118: 0.9418 | O118: 2 | P118: 0.0837 | Q118: 99.7408 | R118: 1.5982 | S118: 101.2007 | T118: 0.5 | U118: 0.4799 | V118: 0.4606 | W118: 0.0048 | X118: 0.4837 | Y118: 0.3946 | Z118: 66 | AA118: 48 | AB118: 72 | AC118: 0-1Y | AD118: 20000 | AE118: 19948.16 | AF118: 19948.16 | AG118: 0.000622 | AH118: =TRUE() -> TRUE | AI118: 2025-04-20 | AJ118: =FALSE() -> FALSE | AK118: =FALSE() -> FALSE | AL118: IN10YT | AM118: 0.2399 | AN118: -0.2388 | AO118: 0.481 | AP118: -0.4764 | AQ118: 0.9665 | AR118: -0.9481
A119: ZTFI-0118 | B119: IN8017046226 | C119: IRFC | D119: Banking | E119: AAA | F119: INR | G119: 100 | H119: 0.0775 | I119: 2 | J119: Fixed | K119: 2021-03-13 | L119: 2029-03-11 | M119: 2024-10-31 | N119: 4.3587 | O119: 8 | P119: 0.0869 | Q119: 96.8802 | R119: 0.2577 | S119: 98.547 | T119: 3.5058 | U119: 3.3598 | V119: 13.837 | W119: 0.0325 | X119: 3.2317 | Y119: 13.8222 | Z119: 44 | AA119: 17 | AB119: 51 | AC119: 3-5Y | AD119: 50000 | AE119: 48440.1 | AF119: 48440.1 | AG119: 0.001511 | AH119: =TRUE() -> TRUE | AI119: 2027-01-04 | AJ119: =FALSE() -> FALSE | AK119: =FALSE() -> FALSE | AL119: IN10YT | AM119: 1.6442 | AN119: -1.6107 | AO119: 3.322 | AP119: -3.188 | AQ119: 6.7781 | AR119: -6.2419
A120: ZTFI-0119 | B120: IN3004786863 | C120: NABARD | D120: Banking | E120: AAA | F120: INR | G120: 100 | H120: 0.075 | I120: 2 | J120: Fixed | K120: 2023-05-28 | L120: 2030-05-26 | M120: 2024-10-31 | N120: 5.5661 | O120: 7 | P120: 0.0775 | Q120: 98.8975 | R120: 1.153 | S120: 100.6529 | T120: 4.6005 | U120: 4.4289 | V120: 24.0074 | W120: 0.0438 | X120: 4.6012 | Y120: 21.273 | Z120: 68 | AA120: 45 | AB120: 65 | AC120: 5-7Y | AD120: 200000 | AE120: 197795 | AF120: 197795 | AG120: 0.00617 | AH120: =TRUE() -> TRUE | AI120: 2027-08-12 | AJ120: =FALSE() -> FALSE | AK120: =FALSE() -> FALSE | AL120: IN10YT | AM120: 2.2197 | AN120: -2.1604 | AO120: 4.4988 | AP120: -4.2614 | AQ120: 9.235 | AR120: -8.2853
A121: ZTFI-0120 | B121: IN0790306738 | C121: HDFC Bank | D121: Infrastructure | E121: AAA | F121: INR | G121: 100 | H121: 0.0743 | I121: 2 | J121: Fixed | K121: 2024-03-12 | L121: 2026-03-12 | M121: 2024-10-31 | N121: 1.3607 | O121: 2 | P121: 0.0879 | Q121: 98.7247 | R121: 1.0701 | S121: 99.7974 | T121: 0.982 | U121: 0.9407 | V121: 1.3433 | W121: 0.0093 | X121: 0.9407 | Y121: 1.3433 | Z121: 72 | AA121: 72 | AB121: 77 | AC121: 1-2Y | AD121: 10000 | AE121: 9872.47 | AF121: 9872.47 | AG121: 0.000308 | AH121: =FALSE() -> FALSE | AJ121: =FALSE() -> FALSE | AK121: =FALSE() -> FALSE | AL121: IN10YT | AM121: 0.466 | AN121: -0.4627 | AO121: 0.9353 | AP121: -0.9221 | AQ121: 1.8839 | AR121: -1.8309
A122: ZTFI-0121 | B122: IN2836440892 | C122: TCS | D122: NBFC | E122: AAA | F122: INR | G122: 100 | H122: 0.0825 | I122: 2 | J122: Fixed | K122: 2020-06-12 | L122: 2028-06-10 | M122: 2024-10-31 | N122: 3.6085 | O122: 8 | P122: 0.0756 | Q122: 102.0876 | R122: 0.7861 | S122: 103.1693 | T122: 3.1151 | U122: 3.0016 | V122: 11.1073 | W122: 0.0306 | X122: 3.0016 | Y122: 11.1073 | Z122: 80 | AA122: 80 | AB122: 88 | AC122: 3-5Y | AD122: 20000 | AE122: 20417.52 | AF122: 20417.52 | AG122: 0.000637 | AH122: =FALSE() -> FALSE | AJ122: =FALSE() -> FALSE | AK122: =FALSE() -> FALSE | AL122: IN10YT | AM122: 1.5463 | AN122: -1.518 | AO122: 3.121 | AP122: -3.0076 | AQ122: 6.3553 | AR122: -5.9017
A123: ZTFI-0122 | B123: IN4628733427 | C123: Bajaj Finance | D123: Banking | E123: AAA | F123: INR | G123: 100 | H123: 0.0883 | I123: 2 | J123: Fixed | K123: 2020-08-15 | L123: 2030-08-13 | M123: 2024-10-31 | N123: 5.7823 | O123: 10 | P123: 0.0804 | Q123: 103.4567 | R123: 0.5629 | S123: 104.1858 | T123: 4.493 | U123: 4.3194 | V123: 23.1603 | W123: 0.0447 | X123: 4.3194 | Y123: 23.1603 | Z123: 28 | AA123: 28 | AB123: 25 | AC123: 5-7Y | AD123: 100000 | AE123: 103456.7 | AF123: 103456.7 | AG123: 0.003227 | AH123: =FALSE() -> FALSE | AJ123: =FALSE() -> FALSE | AK123: =FALSE() -> FALSE | AL123: IN10YT | AM123: 2.2643 | AN123: -2.2044 | AO123: 4.5885 | AP123: -4.3489 | AQ123: 9.4166 | AR123: -8.4582
A124: ZTFI-0123 | B124: IN1830469901 | C124: LIC Housing | D124: NBFC | E124: AAA | F124: INR | G124: 100 | H124: 0.0738 | I124: 2 | J124: Fixed | K124: 2022-05-20 | L124: 2032-05-17 | M124: 2024-10-31 | N124: 7.5428 | O124: 10 | P124: 0.0777 | Q124: 97.8144 | R124: 0.0283 | S124: 99.5435 | T124: 5.8705 | U124: 5.651 | V124: 39.8104 | W124: 0.0553 | X124: 5.651 | Y124: 39.8104 | Z124: 39 | AA124: 39 | AB124: 37 | AC124: 7-10Y | AD124: 20000 | AE124: 19562.88 | AF124: 19562.88 | AG124: 0.00061 | AH124: =FALSE() -> FALSE | AJ124: =FALSE() -> FALSE | AK124: =FALSE() -> FALSE | AL124: IN10YT | AM124: 2.8124 | AN124: -2.7151 | AO124: 5.7222 | AP124: -5.3328 | AQ124: 11.8338 | AR124: -10.2762
A125: ZTFI-0124 | B125: IN3936385467 | C125: IRFC | D125: NBFC | E125: AAA | F125: INR | G125: 100 | H125: 0.0807 | I125: 2 | J125: Fixed | K125: 2022-06-27 | L125: 2029-06-25 | M125: 2024-10-31 | N125: 4.6489 | O125: 7 | P125: 0.0797 | Q125: 100.372 | R125: 1.5366 | S125: 101.0181 | T125: 3.8629 | U125: 3.7149 | V125: 16.9243 | W125: 0.0373 | X125: 3.6046 | Y125: 15.1801 | Z125: 49 | AA125: 24 | AB125: 45 | AC125: 3-5Y | AD125: 50000 | AE125: 50186 | AF125: 50186 | AG125: 0.001565 | AH125: =TRUE() -> TRUE | AI125: 2027-02-26 | AJ125: =FALSE() -> FALSE | AK125: =FALSE() -> FALSE | AL125: IN10YT | AM125: 1.8856 | AN125: -1.8431 | AO125: 3.8137 | AP125: -3.6438 | AQ125: 7.7972 | AR125: -7.1177
A126: ZTFI-0125 | B126: IN2048996423 | C126: Power Finance Corp | D126: Banking | E126: AAA | F126: INR | G126: 100 | H126: 0.0766 | I126: 2 | J126: Fixed | K126: 2020-05-07 | L126: 2028-05-05 | M126: 2024-10-31 | N126: 3.5099 | O126: 8 | P126: 0.0782 | Q126: 99.5182 | R126: 0.6464 | S126: 100.98 | T126: 3.1346 | U126: 3.0166 | V126: 11.1755 | W126: 0.03 | X126: 3.0166 | Y126: 11.1755 | Z126: 61 | AA126: 61 | AB126: 71 | AC126: 3-5Y | AD126: 100000 | AE126: 99518.2 | AF126: 99518.2 | AG126: 0.003104 | AH126: =FALSE() -> FALSE | AJ126: =FALSE() -> FALSE | AK126: =FALSE() -> FALSE | AL126: IN10YT | AM126: 1.5149 | AN126: -1.4871 | AO126: 3.0577 | AP126: -2.9465 | AQ126: 6.2266 | AR126: -5.7817
A127: ZTFI-0126 | B127: IN7725228728 | C127: IRFC | D127: Infrastructure | E127: AAA | F127: INR | G127: 100 | H127: 0.0898 | I127: 2 | J127: Fixed | K127: 2023-10-24 | L127: 2025-10-23 | M127: 2024-10-31 | N127: 0.9774 | O127: 2 | P127: 0.0859 | Q127: 100.187 | R127: 0.1089 | S127: 100.2013 | T127: 0.5 | U127: 0.4794 | V127: 0.4597 | W127: 0.0048 | X127: 0.4794 | Y127: 0.4597 | Z127: 80 | AA127: 80 | AB127: 79 | AC127: 0-1Y | AD127: 5000 | AE127: 5009.35 | AF127: 5009.35 | AG127: 0.000156 | AH127: =FALSE() -> FALSE | AJ127: =FALSE() -> FALSE | AK127: =FALSE() -> FALSE | AL127: IN10YT | AM127: 0.2407 | AN127: -0.2396 | AO127: 0.4826 | AP127: -0.478 | AQ127: 0.9698 | AR127: -0.9514
A128: ZTFI-0127 | B128: IN1203875099 | C128: REC Ltd | D128: Banking | E128: AAA | F128: INR | G128: 100 | H128: 0.0883 | I128: 2 | J128: Fixed | K128: 2024-03-17 | L128: 2033-03-15 | M128: 2024-10-31 | N128: 8.3696 | O128: 9 | P128: 0.0819 | Q128: 103.7027 | R128: 1.1826 | S128: 104.3356 | T128: 5.944 | U128: 5.7102 | V128: 41.7331 | W128: 0.0592 | X128: 5.7115 | Y128: 39.8417 | Z128: 20 | AA128: 2 | AB128: 28 | AC128: 7-10Y | AD128: 50000 | AE128: 51851.35 | AF128: 51851.35 | AG128: 0.001617 | AH128: =TRUE() -> TRUE | AI128: 2029-01-05 | AJ128: =FALSE() -> FALSE | AK128: =FALSE() -> FALSE | AL128: IN10YT | AM128: 3.0149 | AN128: -2.9067 | AO128: 6.138 | AP128: -5.7052 | AQ128: 12.7088 | AR128: -10.9777
A129: ZTFI-0128 | B129: IN1182339845 | C129: NHAI | D129: Banking | E129: AAA | F129: INR | G129: 100 | H129: 0.0753 | I129: 2 | J129: Fixed | K129: 2023-10-13 | L129: 2031-10-11 | M129: 2024-10-31 | N129: 6.9432 | O129: 8 | P129: 0.0875 | Q129: 94.0481 | R129: 1.3125 | S129: 94.6128 | T129: 5.2117 | U129: 4.9932 | V129: 30.9369 | W129: 0.047 | X129: 4.9932 | Y129: 30.9369 | Z129: 56 | AA129: 56 | AB129: 53 | AC129: 5-7Y | AD129: 50000 | AE129: 47024.05 | AF129: 47024.05 | AG129: 0.001467 | AH129: =FALSE() -> FALSE | AJ129: =FALSE() -> FALSE | AK129: =FALSE() -> FALSE | AL129: IN10YT | AM129: 2.3844 | AN129: -2.3116 | AO129: 4.8415 | AP129: -4.5505 | AQ129: 9.9739 | AR129: -8.8101
A130: ZTFI-0129 | B130: IN0166687002 | C130: REC Ltd | D130: Infrastructure | E130: AAA | F130: INR | G130: 100 | H130: 0.0717 | I130: 2 | J130: Fixed | K130: 2019-10-28 | L130: 2027-10-26 | M130: 2024-10-31 | N130: 2.9843 | O130: 8 | P130: 0.0793 | Q130: 98.3066 | R130: 1.6476 | S130: 98.7185 | T130: 2.3312 | U130: 2.2423 | V130: 6.3171 | W130: 0.022 | X130: 2.2423 | Y130: 6.3171 | Z130: 26 | AA130: 26 | AB130: 36 | AC130: 2-3Y | AD130: 500000 | AE130: 491533 | AF130: 491533 | AG130: 0.015332 | AH130: =FALSE() -> FALSE | AJ130: =FALSE() -> FALSE | AK130: =FALSE() -> FALSE | AL130: IN10YT | AM130: 1.1099 | AN130: -1.0944 | AO130: 2.2354 | AP130: -2.1733 | AQ130: 4.5329 | AR130: -4.2845
A131: ZTFI-0130 | B131: IN1489025039 | C131: Infosys | D131: Banking | E131: AAA | F131: INR | G131: 100 | H131: 0.0729 | I131: 2 | J131: Fixed | K131: 2017-11-02 | L131: 2025-10-31 | M131: 2024-10-31 | N131: 0.9993 | O131: 8 | P131: 0.0789 | Q131: 99.7114 | R131: 1.5481 | S131: 100.9453 | T131: 0.5 | U131: 0.481 | V131: 0.4628 | W131: 0.0048 | X131: 0.481 | Y131: 0.4628 | Z131: 35 | AA131: 35 | AB131: 40 | AC131: 0-1Y | AD131: 100000 | AE131: 99711.4 | AF131: 99711.4 | AG131: 0.00311 | AH131: =FALSE() -> FALSE | AJ131: =FALSE() -> FALSE | AK131: =FALSE() -> FALSE | AL131: IN10YT | AM131: 0.2404 | AN131: -0.2392 | AO131: 0.4819 | AP131: -0.4773 | AQ131: 0.9685 | AR131: -0.95
A132: ZTFI-0131 | B132: IN2185016315 | C132: Bajaj Finance | D132: Infrastructure | E132: AAA | F132: INR | G132: 100 | H132: 0.0821 | I132: 2 | J132: Fixed | K132: 2017-07-22 | L132: 2025-07-20 | M132: 2024-10-31 | N132: 0.7173 | O132: 8 | P132: 0.0792 | Q132: 100.1395 | R132: 0.9248 | S132: 100.6078 | T132: 0.5 | U132: 0.481 | V132: 0.4626 | W132: 0.0048 | X132: 0.481 | Y132: 0.4626 | Z132: 37 | AA132: 37 | AB132: 44 | AC132: 0-1Y | AD132: 200000 | AE132: 200279 | AF132: 200279 | AG132: 0.006247 | AH132: =FALSE() -> FALSE | AJ132: =FALSE() -> FALSE | AK132: =FALSE() -> FALSE | AL132: IN10YT | AM132: 0.2414 | AN132: -0.2403 | AO132: 0.484 | AP132: -0.4794 | AQ132: 0.9726 | AR132: -0.9541
A133: ZTFI-0132 | B133: IN9619431142 | C133: Bajaj Finance | D133: Banking | E133: AAA | F133: INR | G133: 100 | H133: 0.0776 | I133: 2 | J133: Fixed | K133: 2022-02-12 | L133: 2026-02-11 | M133: 2024-10-31 | N133: 1.2813 | O133: 4 | P133: 0.0791 | Q133: 99.8585 | R133: 0.8628 | S133: 101.3355 | T133: 0.9813 | U133: 0.944 | V133: 1.3534 | W133: 0.0094 | X133: 0.9065 | Y133: 1.1681 | Z133: 25 | AA133: 6 | AB133: 33 | AC133: 1-2Y | AD133: 5000 | AE133: 4992.93 | AF133: 4992.93 | AG133: 0.000156 | AH133: =TRUE() -> TRUE | AI133: 2025-06-21 | AJ133: =FALSE() -> FALSE | AK133: =FALSE() -> FALSE | AL133: IN10YT | AM133: 0.473 | AN133: -0.4696 | AO133: 0.9494 | AP133: -0.9359 | AQ133: 1.9124 | AR133: -1.8583
A134: ZTFI-0133 | B134: IN8861015819 | C134: LIC Housing | D134: Infrastructure | E134: AAA | F134: INR | G134: 100 | H134: 0.082 | I134: 2 | J134: Fixed | K134: 2019-02-26 | L134: 2026-02-24 | M134: 2024-10-31 | N134: 1.3169 | O134: 7 | P134: 0.0752 | Q134: 100.6435 | R134: 1.4859 | S134: 101.7905 | T134: 0.9804 | U134: 0.9449 | V134: 1.3568 | W134: 0.0095 | X134: 0.9449 | Y134: 1.3568 | Z134: 44 | AA134: 44 | AB134: 46 | AC134: 1-2Y | AD134: 50000 | AE134: 50321.75 | AF134: 50321.75 | AG134: 0.00157 | AH134: =FALSE() -> FALSE | AJ134: =FALSE() -> FALSE | AK134: =FALSE() -> FALSE | AL134: IN10YT | AM134: 0.4772 | AN134: -0.4738 | AO134: 0.9578 | AP134: -0.9442 | AQ134: 1.9293 | AR134: -1.8747
A135: ZTFI-0134 | B135: IN2622444721 | C135: Power Finance Corp | D135: Infrastructure | E135: AAA | F135: INR | G135: 100 | H135: 0.0733 | I135: 2 | J135: Fixed | K135: 2022-03-25 | L135: 2028-03-23 | M135: 2024-10-31 | N135: 3.3922 | O135: 6 | P135: 0.0813 | Q135: 97.9076 | R135: 0.4519 | S135: 99.053 | T135: 2.7439 | U135: 2.6367 | V135: 8.5992 | W135: 0.0258 | X135: 2.6367 | Y135: 8.5992 | Z135: 43 | AA135: 43 | AB135: 44 | AC135: 3-5Y | AD135: 5000 | AE135: 4895.38 | AF135: 4895.38 | AG135: 0.000153 | AH135: =FALSE() -> FALSE | AJ135: =FALSE() -> FALSE | AK135: =FALSE() -> FALSE | AL135: IN10YT | AM135: 1.3013 | AN135: -1.2802 | AO135: 2.6236 | AP135: -2.5394 | AQ135: 5.3314 | AR135: -4.9947
A136: ZTFI-0135 | B136: IN2406596575 | C136: LIC Housing | D136: Banking | E136: AAA | F136: INR | G136: 100 | H136: 0.0786 | I136: 2 | J136: Fixed | K136: 2023-06-08 | L136: 2027-06-07 | M136: 2024-10-31 | N136: 2.5982 | O136: 4 | P136: 0.0828 | Q136: 99.0688 | R136: 0.3491 | S136: 99.8513 | T136: 2.317 | U136: 2.2249 | V136: 6.2438 | W136: 0.022 | X136: 2.2249 | Y136: 6.2438 | Z136: 32 | AA136: 32 | AB136: 37 | AC136: 2-3Y | AD136: 200000 | AE136: 198137.6 | AF136: 198137.6 | AG136: 0.00618 | AH136: =FALSE() -> FALSE | AJ136: =FALSE() -> FALSE | AK136: =FALSE() -> FALSE | AL136: IN10YT | AM136: 1.1098 | AN136: -1.0944 | AO136: 2.2351 | AP136: -2.1733 | AQ136: 4.5321 | AR136: -4.2847
A137: ZTFI-0136 | B137: IN7935646519 | C137: Infosys | D137: Infrastructure | E137: AAA | F137: INR | G137: 100 | H137: 0.074 | I137: 2 | J137: Fixed | K137: 2022-09-19 | L137: 2032-09-16 | M137: 2024-10-31 | N137: 7.8768 | O137: 10 | P137: 0.085 | Q137: 93.9904 | R137: 1.7445 | S137: 94.3782 | T137: 5.8285 | U137: 5.5909 | V137: 39.157 | W137: 0.0525 | X137: 5.5909 | Y137: 39.157 | Z137: 80 | AA137: 80 | AB137: 84 | AC137: 7-10Y | AD137: 5000 | AE137: 4699.52 | AF137: 4699.52 | AG137: 0.000147 | AH137: =FALSE() -> FALSE | AJ137: =FALSE() -> FALSE | AK137: =FALSE() -> FALSE | AL137: IN10YT | AM137: 2.6735 | AN137: -2.5814 | AO137: 5.4389 | AP137: -5.0709 | AQ137: 11.2459 | AR137: -9.7737
A138: ZTFI-0137 | B138: IN6724342661 | C138: IRFC | D138: Banking | E138: AAA | F138: INR | G138: 100 | H138: 0.079 | I138: 2 | J138: Fixed | K138: 2019-09-06 | L138: 2028-09-03 | M138: 2024-10-31 | N138: 3.8412 | O138: 9 | P138: 0.0819 | Q138: 99.1327 | R138: 0.0726 | S138: 101.0453 | T138: 3.1234 | U138: 3.0005 | V138: 11.0819 | W138: 0.0297 | X138: 3.0005 | Y138: 11.0819 | Z138: 64 | AA138: 64 | AB138: 61 | AC138: 3-5Y | AD138: 500000 | AE138: 495663.5 | AF138: 495663.5 | AG138: 0.015461 | AH138: =FALSE() -> FALSE | AJ138: =FALSE() -> FALSE | AK138: =FALSE() -> FALSE | AL138: IN10YT | AM138: 1.501 | AN138: -1.4735 | AO138: 3.0294 | AP138: -2.9195 | AQ138: 6.1687 | AR138: -5.7292
A139: ZTFI-0138 | B139: IN5290965610 | C139: HDFC Bank | D139: Banking | E139: AAA | F139: INR | G139: 100 | H139: 0.072 | I139: 2 | J139: Fixed | K139: 2022-04-17 | L139: 2027-04-16 | M139: 2024-10-31 | N139: 2.4559 | O139: 5 | P139: 0.0817 | Q139: 98.243 | R139: 0.8024 | S139: 98.947 | T139: 1.8971 | U139: 1.8226 | V139: 4.2997 | W139: 0.0179 | X139: 1.8226 | Y139: 4.2997 | Z139: 64 | AA139: 64 | AB139: 63 | AC139: 2-3Y | AD139: 100000 | AE139: 98243 | AF139: 98243 | AG139: 0.003064 | AH139: =FALSE() -> FALSE | AJ139: =FALSE() -> FALSE | AK139: =FALSE() -> FALSE | AL139: IN10YT | AM139: 0.9006 | AN139: -0.89 | AO139: 1.8117 | AP139: -1.7695 | AQ139: 3.6656 | AR139: -3.4967
A140: ZTFI-0139 | B140: IN7146112545 | C140: SBI | D140: Banking | E140: AAA | F140: INR | G140: 100 | H140: 0.0791 | I140: 2 | J140: Fixed | K140: 2022-04-02 | L140: 2027-04-01 | M140: 2024-10-31 | N140: 2.4148 | O140: 5 | P140: 0.0795 | Q140: 99.9274 | R140: 0.8947 | S140: 100.0602 | T140: 1.8887 | U140: 1.8165 | V140: 4.2829 | W140: 0.0182 | X140: 1.8165 | Y140: 4.2829 | Z140: 48 | AA140: 48 | AB140: 44 | AC140: 2-3Y | AD140: 5000 | AE140: 4996.37 | AF140: 4996.37 | AG140: 0.000156 | AH140: =FALSE() -> FALSE | AJ140: =FALSE() -> FALSE | AK140: =FALSE() -> FALSE | AL140: IN10YT | AM140: 0.9129 | AN140: -0.9022 | AO140: 1.8366 | AP140: -1.7938 | AQ140: 3.716 | AR140: -3.5448
A141: ZTFI-0140 | B141: IN1051238282 | C141: NHAI | D141: Infrastructure | E141: AAA | F141: INR | G141: 100 | H141: 0.0766 | I141: 2 | J141: Fixed | K141: 2017-08-18 | L141: 2025-08-16 | M141: 2024-10-31 | N141: 0.7912 | O141: 8 | P141: 0.078 | Q141: 99.9326 | R141: 1.2265 | S141: 100.7601 | T141: 0.5 | U141: 0.4812 | V141: 0.4632 | W141: 0.0048 | X141: 0.4812 | Y141: 0.4632 | Z141: 60 | AA141: 60 | AB141: 55 | AC141: 0-1Y | AD141: 50000 | AE141: 49966.3 | AF141: 49966.3 | AG141: 0.001559 | AH141: =FALSE() -> FALSE | AJ141: =FALSE() -> FALSE | AK141: =FALSE() -> FALSE | AL141: IN10YT | AM141: 0.241 | AN141: -0.2399 | AO141: 0.4832 | AP141: -0.4786 | AQ141: 0.971 | AR141: -0.9525
A142: ZTFI-0141 | B142: IN3796603341 | C142: IRFC | D142: Infrastructure | E142: AAA | F142: INR | G142: 100 | H142: 0.0815 | I142: 2 | J142: Fixed | K142: 2022-08-27 | L142: 2032-08-24 | M142: 2024-10-31 | N142: 7.8138 | O142: 10 | P142: 0.0792 | Q142: 101.2822 | R142: 1.7576 | S142: 102.3574 | T142: 5.7682 | U142: 5.5485 | V142: 38.7699 | W142: 0.0562 | X142: 5.5485 | Y142: 38.7699 | Z142: 27 | AA142: 27 | AB142: 32 | AC142: 7-10Y | AD142: 50000 | AE142: 50641.1 | AF142: 50641.1 | AG142: 0.00158 | AH142: =FALSE() -> FALSE | AJ142: =FALSE() -> FALSE | AK142: =FALSE() -> FALSE | AL142: IN10YT | AM142: 2.8589 | AN142: -2.7607 | AO142: 5.816 | AP142: -5.4233 | AQ142: 12.0246 | AR142: -10.4539
A143: ZTFI-0142 | B143: IN9691557924 | C143: Power Finance Corp | D143: NBFC | E143: AAA | F143: INR | G143: 100 | H143: 0.0884 | I143: 2 | J143: Fixed | K143: 2022-12-28 | L143: 2025-12-27 | M143: 2024-10-31 | N143: 1.1554 | O143: 3 | P143: 0.0791 | Q143: 100.8776 | R143: 1.5325 | S143: 102.0065 | T143: 0.9789 | U143: 0.9417 | V143: 1.349 | W143: 0.0095 | X143: 0.934 | Y143: 1.1745 | Z143: 39 | AA143: 18 | AB143: 46 | AC143: 1-2Y | AD143: 10000 | AE143: 10087.76 | AF143: 10087.76 | AG143: 0.000315 | AH143: =TRUE() -> TRUE | AI143: 2025-05-29 | AJ143: =FALSE() -> FALSE | AK143: =FALSE() -> FALSE | AL143: IN10YT | AM143: 0.4767 | AN143: -0.4733 | AO143: 0.9568 | AP143: -0.9432 | AQ143: 1.9271 | AR143: -1.8727
...

Sheet Portfolio_Summary
B2: Bond Portfolio Convexity Sensitivity — Risk Summary
B3: All KPIs are live formulas referencing Bond_Data — recalculates if source data changes
B4: Key Risk Indicators
B5: Total Market Value (INR) | D5: =SUM(Bond_Data!AF2:AF301) -> 32059346
B6: Number of Bonds | D6: =COUNTA(Bond_Data!A2:A301) -> 300
B7: Portfolio Modified Duration (yrs) | D7: =SUMPRODUCT(Bond_Data!AF2:AF301,Bond_Data!U2:U301)/SUM(Bond_Data!AF2:AF301) -> 4.2031277
B8: Portfolio Macaulay Duration (yrs) | D8: =SUMPRODUCT(Bond_Data!AF2:AF301,Bond_Data!T2:T301)/SUM(Bond_Data!AF2:AF301) -> 4.3348287
B9: Portfolio Convexity | D9: =SUMPRODUCT(Bond_Data!AF2:AF301,Bond_Data!V2:V301)/SUM(Bond_Data!AF2:AF301) -> 44.061199
B10: Portfolio DV01 (INR / 1bp) | D10: =SUMPRODUCT(Bond_Data!W2:W301,Bond_Data!AD2:AD301)/100 -> 8948.2485
B11: Portfolio Yield to Maturity (wtd, %) | D11: =SUMPRODUCT(Bond_Data!AF2:AF301,Bond_Data!P2:P301)/SUM(Bond_Data!AF2:AF301)*100 -> 7.2814237
B14: Parallel Shift Price Sensitivity (Duration + Convexity Approximation)
B15: Shift (bps) | C15: Est. Price Change (%) | D15: Est. P&L (INR)
B16: -200 | C16: =(-$D$7*(B16/10000)+0.5*$D$9*(B16/10000)^2)*100 -> 9.2874793 | D16: =C16/100*$D$5 -> 2977505.1
B17: -100 | C17: =(-$D$7*(B17/10000)+0.5*$D$9*(B17/10000)^2)*100 -> 4.4234337 | D17: =C17/100*$D$5 -> 1418123.9
B18: -50 | C18: =(-$D$7*(B18/10000)+0.5*$D$9*(B18/10000)^2)*100 -> 2.1566403 | D18: =C18/100*$D$5 -> 691404.78
B19: -25 | C19: =(-$D$7*(B19/10000)+0.5*$D$9*(B19/10000)^2)*100 -> 1.064551 | D19: =C19/100*$D$5 -> 341288.1
B20: 25 | C20: =(-$D$7*(B20/10000)+0.5*$D$9*(B20/10000)^2)*100 -> -1.0370128 | D20: =C20/100*$D$5 -> -332459.52
B21: 50 | C21: =(-$D$7*(B21/10000)+0.5*$D$9*(B21/10000)^2)*100 -> -2.0464873 | D21: =C21/100*$D$5 -> -656090.45
B22: 100 | C22: =(-$D$7*(B22/10000)+0.5*$D$9*(B22/10000)^2)*100 -> -3.9828217 | D22: =C22/100*$D$5 -> -1276866.6
B23: 200 | C23: =(-$D$7*(B23/10000)+0.5*$D$9*(B23/10000)^2)*100 -> -7.5250313 | D23: =C23/100*$D$5 -> -2412475.8

Sheet Bucket_Exposure
B2: Key-Rate Bucket Exposure (formula-driven via SUMIFS)
B4: Bucket | C4: Market Value (INR) | D4: Weight (%) | E4: Wtd. Avg Duration | F4: Wtd. Avg Convexity
B5: 0-1Y | C5: =SUMIFS(Bond_Data!AF2:AF301,Bond_Data!AC2:AC301,B5) -> 3014988.4 | D5: =C5/SUM(Bond_Data!AF2:AF301)*100 -> 9.4043978 | E5: =SUMPRODUCT((Bond_Data!AC2:AC301=B5)*Bond_Data!AF2:AF301,Bond_Data!U2:U301)/SUMIFS(Bond_Data!AF2:AF301,Bond_Data!AC2:AC301,B5) -> 0.48123877 | F5: =SUMPRODUCT((Bond_Data!AC2:AC301=B5)*Bond_Data!AF2:AF301,Bond_Data!V2:V301)/SUMIFS(Bond_Data!AF2:AF301,Bond_Data!AC2:AC301,B5) -> 0.4632207
B6: 1-2Y | C6: =SUMIFS(Bond_Data!AF2:AF301,Bond_Data!AC2:AC301,B6) -> 6162504.2 | D6: =C6/SUM(Bond_Data!AF2:AF301)*100 -> 19.222177 | E6: =SUMPRODUCT((Bond_Data!AC2:AC301=B6)*Bond_Data!AF2:AF301,Bond_Data!U2:U301)/SUMIFS(Bond_Data!AF2:AF301,Bond_Data!AC2:AC301,B6) -> 1.0998024 | F6: =SUMPRODUCT((Bond_Data!AC2:AC301=B6)*Bond_Data!AF2:AF301,Bond_Data!V2:V301)/SUMIFS(Bond_Data!AF2:AF301,Bond_Data!AC2:AC301,B6) -> 1.8012436
B7: 2-3Y | C7: =SUMIFS(Bond_Data!AF2:AF301,Bond_Data!AC2:AC301,B7) -> 6913492.4 | D7: =C7/SUM(Bond_Data!AF2:AF301)*100 -> 21.564671 | E7: =SUMPRODUCT((Bond_Data!AC2:AC301=B7)*Bond_Data!AF2:AF301,Bond_Data!U2:U301)/SUMIFS(Bond_Data!AF2:AF301,Bond_Data!AC2:AC301,B7) -> 2.0103671 | F7: =SUMPRODUCT((Bond_Data!AC2:AC301=B7)*Bond_Data!AF2:AF301,Bond_Data!V2:V301)/SUMIFS(Bond_Data!AF2:AF301,Bond_Data!AC2:AC301,B7) -> 5.1989007
B8: 3-5Y | C8: =SUMIFS(Bond_Data!AF2:AF301,Bond_Data!AC2:AC301,B8) -> 4701036.7 | D8: =C8/SUM(Bond_Data!AF2:AF301)*100 -> 14.663545 | E8: =SUMPRODUCT((Bond_Data!AC2:AC301=B8)*Bond_Data!AF2:AF301,Bond_Data!U2:U301)/SUMIFS(Bond_Data!AF2:AF301,Bond_Data!AC2:AC301,B8) -> 2.9523074 | F8: =SUMPRODUCT((Bond_Data!AC2:AC301=B8)*Bond_Data!AF2:AF301,Bond_Data!V2:V301)/SUMIFS(Bond_Data!AF2:AF301,Bond_Data!AC2:AC301,B8) -> 10.869606
B9: 5-7Y | C9: =SUMIFS(Bond_Data!AF2:AF301,Bond_Data!AC2:AC301,B9) -> 2713024.6 | D9: =C9/SUM(Bond_Data!AF2:AF301)*100 -> 8.4625078 | E9: =SUMPRODUCT((Bond_Data!AC2:AC301=B9)*Bond_Data!AF2:AF301,Bond_Data!U2:U301)/SUMIFS(Bond_Data!AF2:AF301,Bond_Data!AC2:AC301,B9) -> 4.5842868 | F9: =SUMPRODUCT((Bond_Data!AC2:AC301=B9)*Bond_Data!AF2:AF301,Bond_Data!V2:V301)/SUMIFS(Bond_Data!AF2:AF301,Bond_Data!AC2:AC301,B9) -> 25.383381
B10: 7-10Y | C10: =SUMIFS(Bond_Data!AF2:AF301,Bond_Data!AC2:AC301,B10) -> 2256811 | D10: =C10/SUM(Bond_Data!AF2:AF301)*100 -> 7.0394792 | E10: =SUMPRODUCT((Bond_Data!AC2:AC301=B10)*Bond_Data!AF2:AF301,Bond_Data!U2:U301)/SUMIFS(Bond_Data!AF2:AF301,Bond_Data!AC2:AC301,B10) -> 6.5334457 | F10: =SUMPRODUCT((Bond_Data!AC2:AC301=B10)*Bond_Data!AF2:AF301,Bond_Data!V2:V301)/SUMIFS(Bond_Data!AF2:AF301,Bond_Data!AC2:AC301,B10) -> 53.086049
B11: 10-15Y | C11: =SUMIFS(Bond_Data!AF2:AF301,Bond_Data!AC2:AC301,B11) -> 1944555 | D11: =C11/SUM(Bond_Data!AF2:AF301)*100 -> 6.0654857 | E11: =SUMPRODUCT((Bond_Data!AC2:AC301=B11)*Bond_Data!AF2:AF301,Bond_Data!U2:U301)/SUMIFS(Bond_Data!AF2:AF301,Bond_Data!AC2:AC301,B11) -> 9.0738398 | F11: =SUMPRODUCT((Bond_Data!AC2:AC301=B11)*Bond_Data!AF2:AF301,Bond_Data!V2:V301)/SUMIFS(Bond_Data!AF2:AF301,Bond_Data!AC2:AC301,B11) -> 101.88921
B12: 15-20Y | C12: =SUMIFS(Bond_Data!AF2:AF301,Bond_Data!AC2:AC301,B12) -> 2541587 | D12: =C12/SUM(Bond_Data!AF2:AF301)*100 -> 7.9277567 | E12: =SUMPRODUCT((Bond_Data!AC2:AC301=B12)*Bond_Data!AF2:AF301,Bond_Data!U2:U301)/SUMIFS(Bond_Data!AF2:AF301,Bond_Data!AC2:AC301,B12) -> 12.367526 | F12: =SUMPRODUCT((Bond_Data!AC2:AC301=B12)*Bond_Data!AF2:AF301,Bond_Data!V2:V301)/SUMIFS(Bond_Data!AF2:AF301,Bond_Data!AC2:AC301,B12) -> 194.19406
B13: 20Y+ | C13: =SUMIFS(Bond_Data!AF2:AF301,Bond_Data!AC2:AC301,B13) -> 1811346.6 | D13: =C13/SUM(Bond_Data!AF2:AF301)*100 -> 5.64998 | E13: =SUMPRODUCT((Bond_Data!AC2:AC301=B13)*Bond_Data!AF2:AF301,Bond_Data!U2:U301)/SUMIFS(Bond_Data!AF2:AF301,Bond_Data!AC2:AC301,B13) -> 12.412718 | F13: =SUMPRODUCT((Bond_Data!AC2:AC301=B13)*Bond_Data!AF2:AF301,Bond_Data!V2:V301)/SUMIFS(Bond_Data!AF2:AF301,Bond_Data!AC2:AC301,B13) -> 238.86886

Sheet Scenario_Data
A1: ScenarioID | B1: ParallelShift_bps | C1: TwistFactor_bps | D1: ButterflyFactor_bps | E1: PnL_DurationEffect_INR | F1: PnL_ConvexityEffect_INR | G1: PnL_Total_INR | H1: PnL_Pct | I1: VaR_Contribution
A2: 1 | B2: -50.28 | C2: -43.61 | D2: -6.73 | E2: 677553.73 | F2: 17857.27 | G2: 695411.01 | H2: 2.1691 | I2: 695411.01
A3: 2 | B3: -103.23 | C3: -5.91 | D3: 3.08 | E3: 1391064.4 | F3: 75270.04 | G3: 1466334.5 | H3: 4.5738 | I3: 1466334.5
A4: 3 | B4: -48.2 | C4: 35.5 | D4: -36.27 | E4: 649560.04 | F4: 16412.18 | G4: 665972.21 | H4: 2.0773 | I4: 665972.21
A5: 4 | B5: 43.03 | C5: 22.37 | D5: 61.3 | E5: -579832.59 | F5: 13077.75 | G5: -566754.84 | H5: -1.7678 | I5: 566754.84
A6: 5 | B6: -5.52 | C6: -51.75 | D6: -16.79 | E6: 74315.99 | F6: 214.83 | G6: 74530.82 | H6: 0.2325 | I6: 74530.82
A7: 6 | B7: 21.14 | C7: -14.71 | D7: -63.45 | E7: -284869.2 | F7: 3156.59 | G7: -281712.6 | H7: -0.8787 | I7: 281712.6
A8: 7 | B8: -13.86 | C8: -51.24 | D8: 20.73 | E8: 186765.86 | F8: 1356.82 | G8: 188122.68 | H8: 0.5868 | I8: 188122.68
A9: 8 | B9: -115.97 | C9: 26.34 | D9: 20.02 | E9: 1562717.1 | F9: 94992.29 | G9: 1657709.4 | H9: 5.1708 | I9: 1657709.4
A10: 9 | B10: 121.75 | C10: -4.45 | D10: -35.68 | E10: -1640530.6 | F10: 104687.86 | G10: -1535842.8 | H10: -4.7906 | I10: 1535842.8
A11: 10 | B11: 199.91 | C11: -40.87 | D11: -15.71 | E11: -2693721.3 | F11: 282249.35 | G11: -2411471.9 | H11: -7.5219 | I11: 2411471.9
A12: 11 | B12: 142.59 | C12: 2.97 | D12: -2.72 | E12: -1921380.2 | F12: 143599.93 | G12: -1777780.2 | H12: -5.5453 | I12: 1777780.2
A13: 12 | B13: 61.34 | C13: -62.95 | D13: 9.16 | E13: -826579.46 | F13: 26576.44 | G13: -800003.02 | H13: -2.4954 | I13: 800003.02
... A1001: 1000 | B1001: 10.38 | C1001: -120.08 | D1001: -12.55 | E1001: -139811.36 | F1001: 760.35 | G1001: -139051.01 | H1001: -0.4337 | I1001: 139051.01

Sheet VaR_Analysis
B2: Monte Carlo VaR / CVaR Analysis (1,000 simulated scenarios)
B4: Confidence Level | C4: VaR (INR) | D4: VaR (%) | E4: CVaR / Expected Shortfall (INR) | F4: CVaR (%)
B5: 0.9 | C5: =-PERCENTILE(Scenario_Data!G2:G1001,1-B5) -> 1467734.1 | D5: =-PERCENTILE(Scenario_Data!H2:H1001,1-B5) -> 4.57821 | E5: =-AVERAGEIF(Scenario_Data!G2:G1001,"<="&(-C5),Scenario_Data!G2:G1001) -> 2033195.5 | F5: =-AVERAGEIF(Scenario_Data!H2:H1001,"<="&(-D5),Scenario_Data!H2:H1001) -> 6.341968
B6: 0.95 | C6: =-PERCENTILE(Scenario_Data!G2:G1001,1-B6) -> 1976671.4 | D6: =-PERCENTILE(Scenario_Data!H2:H1001,1-B6) -> 6.165655 | E6: =-AVERAGEIF(Scenario_Data!G2:G1001,"<="&(-C6),Scenario_Data!G2:G1001) -> 2377153.7 | F6: =-AVERAGEIF(Scenario_Data!H2:H1001,"<="&(-D6),Scenario_Data!H2:H1001) -> 7.414846
B7: 0.99 | C7: =-PERCENTILE(Scenario_Data!G2:G1001,1-B7) -> 2517271 | D7: =-PERCENTILE(Scenario_Data!H2:H1001,1-B7) -> 7.85193 | E7: =-AVERAGEIF(Scenario_Data!G2:G1001,"<="&(-C7),Scenario_Data!G2:G1001) -> 2999457.1 | F7: =-AVERAGEIF(Scenario_Data!H2:H1001,"<="&(-D7),Scenario_Data!H2:H1001) -> 9.35595
B10: Distribution Stats
B11: Mean P&L (INR) | C11: =AVERAGE(Scenario_Data!G2:G1001) -> 84166.302
B12: Std Dev P&L (INR) | C12: =STDEV(Scenario_Data!G2:G1001) -> 1293117.2
B13: Min P&L (INR) | C13: =MIN(Scenario_Data!G2:G1001) -> -3399503.9
B14: Max P&L (INR) | C14: =MAX(Scenario_Data!G2:G1001) -> 5948564.1
B15: Skewness | C15: =SKEW(Scenario_Data!G2:G1001) -> 0.31418464
B16: Kurtosis | C16: =KURT(Scenario_Data!G2:G1001) -> 0.26633514

Sheet Sector_Exposure
B2: Sector & Credit Rating Concentration
B4: Sector | C4: Market Value (INR) | D4: Weight (%) | E4: Wtd Avg Duration | F4: Wtd Avg OAS (bps)
B5: Banking | C5: =SUMIFS(Bond_Data!AF2:AF301,Bond_Data!D2:D301,B5) -> 1768793.1 | D5: =C5/SUM(Bond_Data!AF2:AF301)*100 -> 5.5172463 | E5: =SUMPRODUCT((Bond_Data!D2:D301=B5)*Bond_Data!AF2:AF301,Bond_Data!U2:U301)/SUMIFS(Bond_Data!AF2:AF301,Bond_Data!D2:D301,B5) -> 2.6966185 | F5: =SUMPRODUCT((Bond_Data!D2:D301=B5)*Bond_Data!AF2:AF301,Bond_Data!AA2:AA301)/SUMIFS(Bond_Data!AF2:AF301,Bond_Data!D2:D301,B5) -> 50.657418
B6: Energy | C6: =SUMIFS(Bond_Data!AF2:AF301,Bond_Data!D2:D301,B6) -> 1025789.7 | D6: =C6/SUM(Bond_Data!AF2:AF301)*100 -> 3.1996588 | E6: =SUMPRODUCT((Bond_Data!D2:D301=B6)*Bond_Data!AF2:AF301,Bond_Data!U2:U301)/SUMIFS(Bond_Data!AF2:AF301,Bond_Data!D2:D301,B6) -> 2.0895798 | F6: =SUMPRODUCT((Bond_Data!D2:D301=B6)*Bond_Data!AF2:AF301,Bond_Data!AA2:AA301)/SUMIFS(Bond_Data!AF2:AF301,Bond_Data!D2:D301,B6) -> 186.82729
B7: Government | C7: =SUMIFS(Bond_Data!AF2:AF301,Bond_Data!D2:D301,B7) -> 18452107 | D7: =C7/SUM(Bond_Data!AF2:AF301)*100 -> 57.556094 | E7: =SUMPRODUCT((Bond_Data!D2:D301=B7)*Bond_Data!AF2:AF301,Bond_Data!U2:U301)/SUMIFS(Bond_Data!AF2:AF301,Bond_Data!D2:D301,B7) -> 6.0175531 | F7: =SUMPRODUCT((Bond_Data!D2:D301=B7)*Bond_Data!AF2:AF301,Bond_Data!AA2:AA301)/SUMIFS(Bond_Data!AF2:AF301,Bond_Data!D2:D301,B7) -> 0
B8: Infrastructure | C8: =SUMIFS(Bond_Data!AF2:AF301,Bond_Data!D2:D301,B8) -> 2785416 | D8: =C8/SUM(Bond_Data!AF2:AF301)*100 -> 8.688312 | E8: =SUMPRODUCT((Bond_Data!D2:D301=B8)*Bond_Data!AF2:AF301,Bond_Data!U2:U301)/SUMIFS(Bond_Data!AF2:AF301,Bond_Data!D2:D301,B8) -> 1.4940021 | F8: =SUMPRODUCT((Bond_Data!D2:D301=B8)*Bond_Data!AF2:AF301,Bond_Data!AA2:AA301)/SUMIFS(Bond_Data!AF2:AF301,Bond_Data!D2:D301,B8) -> 101.9379
B9: NBFC | C9: =SUMIFS(Bond_Data!AF2:AF301,Bond_Data!D2:D301,B9) -> 7208368 | D9: =C9/SUM(Bond_Data!AF2:AF301)*100 -> 22.484451 | E9: =SUMPRODUCT((Bond_Data!D2:D301=B9)*Bond_Data!AF2:AF301,Bond_Data!U2:U301)/SUMIFS(Bond_Data!AF2:AF301,Bond_Data!D2:D301,B9) -> 1.5122885 | F9: =SUMPRODUCT((Bond_Data!D2:D301=B9)*Bond_Data!AF2:AF301,Bond_Data!AA2:AA301)/SUMIFS(Bond_Data!AF2:AF301,Bond_Data!D2:D301,B9) -> 81.978016
B10: Steel | C10: =SUMIFS(Bond_Data!AF2:AF301,Bond_Data!D2:D301,B10) -> 818872.05 | D10: =C10/SUM(Bond_Data!AF2:AF301)*100 -> 2.5542382 | E10: =SUMPRODUCT((Bond_Data!D2:D301=B10)*Bond_Data!AF2:AF301,Bond_Data!U2:U301)/SUMIFS(Bond_Data!AF2:AF301,Bond_Data!D2:D301,B10) -> 2.1214672 | F10: =SUMPRODUCT((Bond_Data!D2:D301=B10)*Bond_Data!AF2:AF301,Bond_Data!AA2:AA301)/SUMIFS(Bond_Data!AF2:AF301,Bond_Data!D2:D301,B10) -> 208.98971

Sheet PowerBI_DAX_Measures
B2: Power BI Data Model — DAX Measures Reference
B3: Copy these measures into a Power BI model built on Bond_Data and Scenario_Data tables.
B5: Total Market Value
B6: Total MV = SUM(Bond_Data[MarketValue_INR])
B8: Portfolio Modified Duration
B9: Port Modified Duration = SUMX(Bond_Data, Bond_Data[MarketValue_INR] * Bond_Data[ModifiedDuration]) / [Total MV]
B11: Portfolio Convexity
B12: Port Convexity = SUMX(Bond_Data, Bond_Data[MarketValue_INR] * Bond_Data[Convexity]) / [Total MV]
B14: Portfolio DV01
B15: Port DV01 = SUMX(Bond_Data, Bond_Data[DV01_Per100Face] * Bond_Data[Quantity] / 100)
B17: Weighted YTM
B18: Wtd YTM = SUMX(Bond_Data, Bond_Data[MarketValue_INR] * Bond_Data[YieldToMaturity]) / [Total MV]
... B47: 5. What-If Rate Shift Simulator — 'Rate Shift' disconnected table + slicer driving Est PnL INR measure
